// C++ program to demonstate property 3: If an exception is
// thrown and not caught anywhere, the program terminates
// abnormally in exception handling.

#include <iostream>
using namespace std;

int main()
{
    try {
        throw 'a';
    }
    catch (int x) {
        cout << "Caught ";
    }
    return 0;
}
